Workbook

Sheet SUM
B2: 2026년 안전보건 상반기 예산 집행내역
B4: 구 분 | C4: 집행액
B5: 총 계 | C5: =SUM(C6:C16) -> 1639691342
B6: 1. 현장 안전시설 개선비용 | C6: ='SUM2'!C12 -> 1386040909
B7: 2. 개인보호구 및 안전장비 구입비용 | C7: ='SUM2'!C19 -> 199424800
B8: 3. 안전보건교육 실시비용(내/외부) | C8: ='SUM2'!C23 -> 1776000
B9: 4. 작업환경 측정 및 근로자 건강검진 실시비용 | C9: ='SUM2'!C27 -> 18852640
B10: 5. 재해예방 기술지도비용 | C10: ='SUM2'!C30 -> 0
B11: 6. 안전관련 행사비용 | C11: ='SUM2'!C33 -> 29517400
B12: 7. 안전보건표지 비용 | C12: ='SUM2'!C36 -> 0
B13: 8. 관련회의 및 토론회 개최비용 | C13: 0
B14: 9. 안전포상비용 | C14: ='SUM2'!C40 -> 650000
B15: 10. 기타비용 | C15: ='SUM2'!C47 -> 3429593
B16: 11. 인건비 | C16: ='SUM2'!C51 -> 0

Sheet SUM2
B2: 2026년 안전보건 상반기 예산 집행내역
B4: 구 분 | C4: 집행액 | D4: 분류 | E4: 1월 | H4: 2월 | K4: 3월 | N4: 4월 | Q4: 5월 | T4: 6월 | W4: 7월 | Z4: 8월 | AC4: 9월 | AF4: 10월 | AI4: 11월 | AL4: 12월
B5: 총 계 | C5: =SUM(E5:AN5) -> 1639691342 | E5: 합 계 | G5: =G12+G19+G23+G27+G30+G33+G36+G38+G40+G47+G51 -> 419579478 | H5: 합 계 | J5: =J12+J19+J23+J27+J30+J33+J36+J38+J40+J47+J51 -> 267480828 | K5: 합 계 | M5: =M12+M19+M23+M27+M30+M33+M36+M38+M40+M47+M51 -> 283145646 | N5: 합 계 | P5: =P12+P19+P23+P27+P30+P33+P36+P38+P40+P47+P51 -> 313938990 | Q5: 합 계 | S5: =S12+S19+S23+S27+S30+S33+S36+S38+S40+S47+S51 -> 321824636 | T5: 합 계 | V5: =V12+V19+V23+V27+V30+V33+V36+V38+V40+V47+V51 -> 4589364 | W5: 합계 | Y5: =Y12+Y19+Y23+Y27+Y30+Y33+Y36+Y38+Y40+Y47+Y51 -> 0 | Z5: 합 계 | AB5: =AB12+AB19+AB23+AB27+AB30+AB33+AB36+AB38+AB40+AB47+AB51 -> 0 | AC5: 합 계 | AE5: =AE12+AE19+AE23+AE27+AE30+AE33+AE36+AE38+AE40+AE47+AE51 -> 0 | AF5: 합 계 | AH5: =AH12+AH19+AH23+AH27+AH30+AH33+AH36+AH38+AH40+AH47+AH51 -> 29132400 | AI5: 합 계 | AK5: =AK12+AK19+AK23+AK27+AK30+AK33+AK36+AK38+AK40+AK47+AK51 -> 0 | AL5: 합 계 | AN5: =AN12+AN19+AN23+AN27+AN30+AN33+AN36+AN38+AN40+AN47+AN51 -> 0
B6: 1. 현장 안전시설 개선비용 | D6: 세부내역 | E6: 건대입구점 등 756건 | F6: 매장시설관리팀 | G6: 312541000 | H6: 주염점 등 578건 | I6: 매장시설관리팀 | J6: 232398000 | K6: 수원인계본점 등 649건 | L6: 매장시설관리팀 | M6: =SUM('5.(매장시설관리팀)'!$E$1339:$E$1987) -> 246648000 | N6: 수원고색점 등 680건 | O6: 매장시설관리팀 | P6: =SUM('5.(매장시설관리팀)'!$E$1988:$E$2667) -> 274190000 | Q6: 인천석바위점 등 686건 | R6: 매장시설관리팀 | S6: =SUM('5.(매장시설관리팀)'!$E$2668:$E$3353) -> 279624909
E7: 투명코너매트(788개) | F7: 총무관리팀 | G7: ='4.(소화기, 매장비품)'!$F$26 -> 7880000 | H7: 투명코너매트(635개) | I7: 총무관리팀 | J7: ='4.(소화기, 매장비품)'!$H$26 -> 6350000 | K7: 투명코너매트(503개) | L7: 총무관리팀 | M7: ='4.(소화기, 매장비품)'!$J$26 -> 5030000 | N7: 투명코너매트(704개) | O7: 총무관리팀 | P7: ='4.(소화기, 매장비품)'!$L$26 -> 7040000 | Q7: 투명코너매트(141개) | R7: 총무관리팀 | S7: ='4.(소화기, 매장비품)'!$N$26 -> 1410000 | T7: 투명코너매트(6개) | U7: 총무관리팀 | V7: ='4.(소화기, 매장비품)'!$P$26 -> 60000
E8: 모서리보호(536개) | F8: 로스관리팀 | G8: ='4.(소화기, 매장비품)'!$F$23 -> 1025000 | H8: 모서리보호(137개) | I8: 로스관리팀 | J8: ='4.(소화기, 매장비품)'!$H$23 -> 272000 | K8: 모서리보호(445개) | L8: 로스관리팀 | M8: ='4.(소화기, 매장비품)'!$J$23 -> 865000 | N8: 모서리보호(1,559개) | O8: 로스관리팀 | P8: ='4.(소화기, 매장비품)'!$L$23 -> 3087000 | Q8: 모서리보호(3,678개) | R8: 로스관리팀 | S8: ='4.(소화기, 매장비품)'!$N$23 -> 7295000
H9: 김포구래2호점 안전모 등 | I9: 신축팀 | J9: ='2.(신축팀)'!$G$8 -> 235000 | K9: 평택팽성점 안전모(10) | L9: 신축팀 | M9: ='2.(신축팀)'!$G$9 -> 90000
C12: =SUM(E12:AN12) -> 1386040909 | D12: 비용 | G12: =SUM(G6:G11) -> 321446000 | J12: =SUM(J6:J11) -> 239255000 | M12: =SUM(M6:M11) -> 252633000 | P12: =SUM(P6:P11) -> 284317000 | S12: =SUM(S6:S11) -> 288329909 | V12: =V6+V7+V8+V9 -> 60000 | Y12: =Y6+Y7+Y8+Y9+Y10 -> 0 | AB12: =SUM(AB6:AB11) -> 0 | AE12: =SUM(AE6:AE11) -> 0 | AH12: =SUM(AH6:AH11) -> 0 | AK12: =SUM(AK6:AK11) -> 0 | AN12: =SUM(AN6:AN11) -> 0
B13: 2. 개인보호구 및 안전장비 구입비용 | D13: 세부내역 | E13: 총무_매장 사다리 구매 [3단] | F13: 총무관리팀 | G13: 37182600 | H13: - | K13: 롯데마트행당역점 | L13: 총무관리팀 | M13: 130000 | N13: 총무_매장 안전모 구매 | O13: 총무관리팀 | P13: 3360000
E14: 총무_매장 사다리 구매 [4단] | F14: 총무관리팀 | G14: 30248000 | K14: 롯데마트맥스창원중앙점 | L14: 총무관리팀 | M14: 140000 | N14: 롯데마트서울역점 | O14: 총무관리팀 | P14: 130000
E15: 남양주화도점 | F15: 총무관리팀 | G15: 121000 | N15: 롯데마트삼산점 | O15: 총무관리팀 | P15: =280000+130000 -> 410000
E16: 대전괴정점 | F16: 총무관리팀 | G16: 121000 | N16: 롯데마트삼산점 | O16: 총무관리팀 | P16: 130000
E17: 소화기 | F17: 총무관리팀 | G17: ='4.(소화기, 매장비품)'!$D$4 -> 4885200 | H17: 소화기 | I17: 총무관리팀 | J17: ='4.(소화기, 매장비품)'!$D$5 -> 10763400 | K17: 소화기 | L17: 총무관리팀 | M17: ='4.(소화기, 매장비품)'!$D$6 -> 6155400 | N17: 소화기 | O17: 총무관리팀 | P17: ='4.(소화기, 매장비품)'!$D$7 -> 4738200 | Q17: 소화기 | R17: 총무관리팀 | S17: ='4.(소화기, 매장비품)'!$D$8 -> 5081000 | T17: 소화기 | U17: 총무관리팀 | V17: ='4.(소화기, 매장비품)'!$D$9 -> 1914000
E18: 작업용 장갑 | F18: 로스관리팀 | G18: ='4.(소화기, 매장비품)'!$F$22 -> 18274000 | H18: 작업용 장갑 | I18: 로스관리팀 | J18: ='4.(소화기, 매장비품)'!$H$22 -> 16638000 | K18: 작업용 장갑 | L18: 로스관리팀 | M18: ='4.(소화기, 매장비품)'!$J$22 -> 19499000 | N18: 작업용 장갑 | O18: 로스관리팀 | P18: ='4.(소화기, 매장비품)'!$L$22 -> 19024000 | Q18: 작업용 장갑 | R18: 로스관리팀 | S18: ='4.(소화기, 매장비품)'!$N$22 -> 20480000
C19: =SUM(E19:AN19) -> 199424800 | D19: 비용 | G19: =SUM(G13:G18) -> 90831800 | J19: =SUM(J13:J18) -> 27401400 | M19: =SUM(M13:M18) -> 25924400 | P19: =SUM(P13:P18) -> 27792200 | S19: =SUM(S13:S18) -> 25561000 | V19: =SUM(V13:V18) -> 1914000 | Y19: =SUM(Y13:Y18) -> 0 | AB19: =SUM(AB13:AB18) -> 0 | AE19: =SUM(AE13:AE18) -> 0 | AH19: =SUM(AH13:AH18) -> 0 | AK19: =SUM(AK13:AK18) -> 0 | AN19: =SUM(AN13:AN18) -> 0
B20: 3. 안전보건교육 실시비용(내/외부) | D20: 세부내역 | E20: 중대재해처벌법 대응 교육(박찬욱, 서유림, 조지현) | F20: 안전보건팀 | G20: 926000 | H20: 보건관리자 신규교육(윤정인) | I20: 안전보건팀 | J20: 310000 | N20: 안전관리자 보수교육(강동현) | O20: 안전보건팀 | P20: 180000 | Q20: 안전관리자 보수교육(유준하) | R20: 안전보건팀 | S20: 184000
E21: 중대재해처벌법과 산업안전보건체계의 구축 실무(박찬욱) | F21: 안전보건팀 | G21: 176000
C23: =SUM(E23:AN23) -> 1776000 | D23: 비용 | G23: =SUM(G20:G22) -> 1102000 | J23: =SUM(J20:J22) -> 310000 | M23: =SUM(M20:M22) -> 0 | P23: =SUM(P20:P22) -> 180000 | S23: =SUM(S20:S22) -> 184000 | V23: =SUM(V20:V22) -> 0 | Y23: =SUM(Y20:Y22) -> 0 | AB23: =SUM(AB20:AB22) -> 0 | AE23: =SUM(AE20:AE22) -> 0 | AH23: =AH20+AH21+AH22 -> 0 | AK23: =SUM(AK20:AK22) -> 0 | AN23: =SUM(AN20:AN22) -> 0
B24: 4. 작업환경 측정 및 근로자 건강검진 실시비용 | D24: 세부내역 | E24: 임원건강검진(5명_배우자 포함) | F24: 안전보건팀 | G24: ='1.건강검진(안전보건,인사)'!$D$4 -> 5000000 | K24: 임원건강검진(4명_배우자 포함) | L24: 안전보건팀 | M24: 4000000 | N24: 임원건강검진(1명_배우자) | O24: 안전보건팀 | P24: 1000000 | Q24: 임원건강검진(6명_배우자 포함) | R24: 안전보건팀 | S24: 6000000 | T24: 26년 상반기 신입/경력 공개채용 채용검진비(64명) | U24: 안전보건팀 | V24: =(16+48)*40000 -> 2560000
E25: 25년 하반기 경력 수시채용 채용검진비(1명) | F25: 인사관리팀 | G25: ='1.건강검진(안전보건,인사)'!$H$4 -> 40000 | K25: 26년 상반기 경력 채용 채용검진비(1명) | L25: 인사관리팀 | M25: 40000 | N25: 26년 상반기 경력 채용 채용검진비(2명) | O25: 인사관리팀 | P25: 80000 | Q25: 특수건강검진(구본찬, 예상훈, 유현철) | R25: 인사관리팀 | S25: 99480
E26: 특수건강검진(문선익) | F26: 안전보건팀 | G26: ='1.건강검진(안전보건,인사)'!$L$4 -> 33160
C27: =SUM(E27:AN27) -> 18852640 | D27: 비용 | G27: =SUM(G24:G26) -> 5073160 | J27: =SUM(J24:J25) -> 0 | M27: =SUM(M24:M26) -> 4040000 | P27: =SUM(P24:P25) -> 1080000 | S27: =SUM(S24:S26) -> 6099480 | V27: =SUM(V24:V26) -> 2560000 | Y27: =SUM(Y24:Y26) -> 0 | AB27: =SUM(AB24:AB26) -> 0 | AE27: =SUM(AE24:AE26) -> 0 | AH27: =SUM(AH24:AH26) -> 0 | AK27: =SUM(AK24:AK26) -> 0 | AN27: =SUM(AN24:AN26) -> 0
B28: 5. 재해예방 기술지도비용 | D28: 세부내역
C30: =SUM(E30:AN30) -> 0 | D30: 비용 | G30: =SUM(G28:G29) -> 0 | J30: =SUM(J28:J29) -> 0 | M30: =SUM(M28:M29) -> 0 | P30: =SUM(P28:P29) -> 0 | S30: =SUM(S28:S29) -> 0 | V30: =SUM(V28:V29) -> 0 | Y30: =SUM(Y28:Y29) -> 0 | AB30: =SUM(AB28:AB29) -> 0 | AE30: =SUM(AE28:AE29) -> 0 | AH30: =SUM(AH28:AH29) -> 0 | AK30: =SUM(AK28:AK29) -> 0 | AN30: =SUM(AN28:AN29) -> 0
B31: 6. 안전관련 행사비용 | D31: 세부내역 | Q31: 매장 워크온 플랫폼 이용비용(보건) | R31: 안전보건팀 | S31: 385000 | AF31: ISO45001 사후심사 비용(KFQ) | AG31: 안전보건팀 | AH31: 29132400
C33: =SUM(E33:AN33) -> 29517400 | D33: 비용 | G33: =SUM(G31:G32) -> 0 | J33: =SUM(J31:J32) -> 0 | M33: =SUM(M31:M32) -> 0 | P33: =SUM(P31:P32) -> 0 | S33: =SUM(S31:S32) -> 385000 | V33: =SUM(V31:V32) -> 0 | Y33: =SUM(Y31:Y32) -> 0 | AB33: =SUM(AB31:AB32) -> 0 | AE33: =SUM(AE31:AE32) -> 0 | AH33: =SUM(AH31:AH32) -> 29132400 | AK33: =AK31 -> 0 | AN33: =SUM(AN31:AN32) -> 0
B34: 7. 안전보건표지 비용 | D34: 세부내역
C36: =SUM(E36:AN36) -> 0 | D36: 비용 | G36: =SUM(G34:G35) -> 0 | J36: =SUM(J34:J35) -> 0 | M36: =SUM(M34) -> 0 | S36: =SUM(S34) -> 0 | V36: =SUM(V34) -> 0 | Y36: =SUM(Y34) -> 0 | AB36: =SUM(AB34) -> 0 | AE36: =SUM(AE34) -> 0 | AH36: =SUM(AH34) -> 0 | AK36: =SUM(AK34) -> 0 | AN36: =SUM(AN34) -> 0
B37: 8. 관련회의 및 토론회 개최비용 | D37: 세부내역
C38: =SUM(E38:AN38) -> 0 | D38: 비용 | G38: =SUM(G37) -> 0 | J38: =SUM(J37) -> 0 | M38: =SUM(M37) -> 0 | S38: =SUM(S37) -> 0 | V38: =SUM(V37) -> 0 | Y38: =SUM(Y37) -> 0 | AB38: =SUM(AB37) -> 0 | AE38: =SUM(AE37) -> 0 | AH38: =SUM(AH37) -> 0 | AK38: =SUM(AK37) -> 0 | AN38: =SUM(AN37) -> 0
B39: 9. 안전포상비용 | D39: 세부내역 | Q39: 매장 워크온 포상비용(보건) | S39: 650000
C40: =SUM(E40:AN40) -> 650000 | D40: 비용 | G40: =SUM(G39) -> 0 | J40: =SUM(J39) -> 0 | M40: =SUM(M39) -> 0 | P40: =SUM(P39) -> 0 | S40: =SUM(S39) -> 650000 | V40: =SUM(V39) -> 0 | Y40: =SUM(Y39) -> 0 | AB40: =SUM(AB39) -> 0 | AE40: =SUM(AE39) -> 0 | AH40: =SUM(AH39) -> 0 | AK40: =SUM(AK39) -> 0 | AN40: =SUM(AN39) -> 0
B41: 10. 기타비용 | D41: 세부내역 | E41: AED 렌탈비(4대) | F41: 총무팀 | G41: 270000 | H41: AED 렌탈비(4대) | I41: 총무팀 | J41: 270000 | K41: AED 렌탈비(4대) | L41: 총무팀 | M41: 270000 | N41: AED 렌탈비(5대) | O41: 총무팀 | P41: 310000 | Q41: AED 렌탈비(5대) | R41: 총무팀 | S41: 320000
E42: 공기청정기 렌탈비 | F42: 총무관리팀 | G42: 160700 | H42: 공기청정기 렌탈비 | I42: 총무관리팀 | J42: 160700 | K42: 공기청정기 렌탈비 | L42: 총무관리팀 | M42: 160700 | N42: 공기청정기 렌탈비 | O42: 총무관리팀 | P42: 160700 | Q42: 공기청정기 렌탈비 | R42: 총무관리팀 | S42: 160700
E43: 의약품구매 | F43: 안전보건팀 | G43: 85818 | H43: 의약품구매 | I43: 안전보건팀 | J43: 83728 | K43: 의약품구매 | L43: 안전보건팀 | M43: 117546 | N43: 의약품구매 | O43: 안전보건팀 | P43: 99090 | Q43: 의약품구매 | R43: 안전보건팀 | S43: 134547 | T43: 의약품구매 | U43: 안전보건팀 | V43: 55364
E44: 대한산업안전협회 연회비 | F44: 안전보건팀 | G44: 360000
E45: 직업건강협회 연회비 | F45: 안전보건팀 | G45: 250000
C47: =SUM(E47:AO47) -> 3429593 | D47: 비용 | G47: =SUM(G41:G46) -> 1126518 | J47: =SUM(J41:J46) -> 514428 | M47: =SUM(M41:M46) -> 548246 | P47: =SUM(P41:P46) -> 569790 | S47: =SUM(S41:S46) -> 615247 | V47: =SUM(V41:V46) -> 55364 | Y47: =SUM(Y41:Y46) -> 0 | AB47: =SUM(AB41:AB46) -> 0 | AE47: =SUM(AE41:AE46) -> 0 | AH47: =SUM(AH41:AH46) -> 0 | AK47: =SUM(AK41:AK46) -> 0 | AN47: =SUM(AN41:AN46) -> 0
B48: 11. 인건비 | D48: 세부내역
C51: =SUM(E51:AN51) -> 0 | D51: 비용 | G51: =SUM(G48:G50) -> 0 | J51: =SUM(J48:J50) -> 0 | M51: =SUM(M48:M50) -> 0 | P51: =SUM(P48:P50) -> 0 | S51: =SUM(S48:S50) -> 0 | V51: =SUM(V48:V50) -> 0 | Y51: =SUM(Y48:Y50) -> 0 | AB51: =SUM(AB48:AB50) -> 0 | AE51: =SUM(AE48:AE50) -> 0 | AH51: =SUM(AH48:AH50) -> 0 | AK51: =SUM(AK48:AK50) -> 0 | AN51: =SUM(AN48:AN50) -> 0
...

Sheet 1.건강검진(안전보건,인사)
B2: 2026년도 임원 건강검진비 | F2: 2026년도 채용 검진비 | J2: 2026년도 특수건강검진비
C3: 내용 | D3: 총 비용(원) | G3: 내용 | H3: 총 비용(원) | K3: 내용 | L3: 총 비용(원)
B4: 1월 | C4: 임원건강검진(5명_배우자 포함) | D4: 5000000 | F4: 1월 | G4: 25년 하반기 경력 수시채용 채용검진비(1명) | H4: 40000 | J4: 1월 | K4: 특수건강검진(문선익) | L4: 33160
B5: 2월 | C5: - | D5: - | F5: 2월 | G5: - | H5: - | J5: 2월 | K5: - | L5: -
B6: 3월 | C6: 임원건강검진(4명_배우자 포함) | D6: 4000000 | F6: 3월 | G6: 26년 상반기 경력 채용 채용검진비(1명) | H6: 40000 | J6: 3월 | K6: - | L6: -
B7: 4월 | C7: 임원건강검진(1명_배우자) | D7: 1000000 | F7: 4월 | G7: 26년 상반기 경력 채용 채용검진비(2명) | H7: 80000 | J7: 4월 | K7: - | L7: -
B8: 5월 | C8: 임원건강검진(6명_배우자 포함) | D8: 6000000 | F8: 5월 | G8: - | H8: - | J8: 5월 | K8: 특수건강검진(구본찬, 예상훈, 유현철) | L8: 99480
B9: 6월 | F9: 6월 | G9: 26년 상반기 신입/경력 공개채용 채용검진비(64명) | H9: =(16+48)*40000 -> 2560000 | J9: 6월
B10: 7월 | F10: 7월 | J10: 7월
B11: 8월 | F11: 8월 | J11: 8월
B12: 9월 | F12: 9월 | J12: 9월
B13: 10월 | F13: 10월 | J13: 10월
B14: 11월 | F14: 11월 | J14: 11월
B15: 12월 | F15: 12월 | J15: 12월
C16: 예시) 임원건강검진(4명_배우자 포함) | D16: =D4+D6+D7+D8 -> 16000000 | G16: 예시_경력 수시채용 채용검진비(10명) | H16: =H4+H6+H7+H9 -> 2720000 | K16: 예시)특수건강검진 (이름) | L16: =SUM(L4:L15) -> 132640

Sheet 2.(신축팀)
B2: 신축팀 2026년도 안전관리비 내역
B4: No. | C4: 매장명 | D4: 오픈일 | E4: 입찰연도 | F4: 항목 | G4: 안전관리비 | H4: 세부내역
B5: 1 | C5: 울주삼남교동점 | D5: 26.02.05 | E5: 2025 | H5: 미사용
B6: 2 | C6: 부산정관신도시2호점 | D6: 26.02.12 | E6: 2025 | H6: 미사용
B7: 3 | C7: 부산덕포점 | D7: 26.02.27 | E7: 2025 | H7: 미사용
B8: 4 | C8: 김포구래2호점 | D8: 26.02.27 | E8: 2026 | F8: 안전관리 | G8: 235000 | H8: 안전모10, 안전벨트2, 구급상자1
B9: 5 | C9: 평택팽성점 | D9: 26.03.07 | E9: 2026 | F9: 안전관리 | G9: 90000 | H9: 안전모10
B10: 6 | C10: 포항성곡점 | D10: 26.05.29 | E10: 2026 | H10: 미사용
B11: 7 | C11: 강릉송정점 | D11: 26.06.26 | E11: 2026 | H11: 정산중
B13: 총계 | G13: =SUM(G5:G12) -> 325000
B14: ※ 2022년 입찰부터 안전관리비 책정 시작 및 인테리어 업체의 사용 내역 증빙 시 비용 인정

Sheet 3.(매장 안전모, 사다리_총무관리)
B2: 3단, 4단, 5단 사다리, 우마형사다리. 사다리 컨베이어, 안전모
B4: 구 분 | C4: 집행액 | D4: 분류 | E4: 1월 | G4: 2월 | I4: 3월 | K4: 4월 | M4: 5월 | O4: 6월 | Q4: 7월 | S4: 8월 | U4: 9월 | W4: 10월 | Y4: 11월 | AA4: 12월
B5: 총 합 계 | C5: =SUM(E166:AA166) -> 31300000 | E5: 총무_매장 사다리 구매 [3단] | F5: 37182600 | I5: 롯데마트행당역점 | J5: 130000 | K5: 총무_매장 안전모 구매 | L5: 3360000
B6: 2. 개인보호구 및 안전장비 구입비용 | D6: 세부내역 | E6: 총무_매장 사다리 구매 [4단] | F6: 30248000 | I6: 롯데마트맥스창원중앙점 | J6: 140000 | K6: 롯데마트서울역점 | L6: 130000
E7: 남양주화도점 | F7: 121000 | K7: 롯데마트삼산점 | L7: =280000+130000 -> 410000
E8: 대전괴정점 | F8: 121000 | K8: 롯데마트삼산점 | L8: 130000
C166: =SUM(E166:AA166) -> 31300000 | D166: 비용 | F166: =SUM(F6:F165) -> 30490000 | H166: =SUM(H6:H165) -> 0 | J166: =SUM(J6:J165) -> 140000 | L166: =SUM(L6:L165) -> 670000 | N166: =SUM(N6:N165) -> 0 | P166: =SUM(P6:P165) -> 0 | R166: =SUM(R6:R165) -> 0 | T166: =SUM(T6:T165) -> 0 | V166: =SUM(V6:V165) -> 0 | X166: =SUM(X6:X165) -> 0 | Z166: =SUM(Z6:Z165) -> 0 | AB166: =SUM(AB6:AB18) -> 0
B168: 3단, 4단, 5단 사다리, 우마형사다리. 사다리 컨베이어, 안전모

Sheet 4.(소화기, 매장비품)
B2: 2026년 매장 소화기 입고건
B3: 분류 | C3: 수량(개) | D3: 공급가액(원)
B4: 1월 | C4: 198 | D4: 4885200
B5: 2월 | C5: 429 | D5: 10763400
B6: 3월 | C6: 259 | D6: 6155400
B7: 4월 | C7: 199 | D7: 4738200
B8: 5월 | C8: 238 | D8: 5081000
B9: 6월 | C9: 90 | D9: 1914000
B10: 7월
B11: 8월
B12: 9월
B13: 10월
B14: 11월
B15: 12월
D16: =SUM(D4:D15) -> 33537200
B18: □ 매장소모품 사용 현황(1월~6월)
B20: 대분류 | C20: 중분류 | D20: 소분류 | E20: 1 | G20: 2 | I20: 3 | K20: 4 | M20: 5 | O20: 6 | Q20: 7 | S20: 8 | U20: 9 | W20: 10 | Y20: 11 | AA20: 12
E21: 수량 | F21: 금액 | G21: 수량 | H21: 금액 | I21: 수량 | J21: 금액 | K21: 수량 | L21: 금액 | M21: 수량 | N21: 금액 | O21: 수량 | P21: 금액 | Q21: 수량 | R21: 금액 | S21: 수량 | T21: 금액 | U21: 수량 | V21: 금액 | W21: 수량 | X21: 금액 | Y21: 수량 | Z21: 금액 | AA21: 수량 | AB21: 금액
B22: 공구/전기 | C22: 수공구용품 | D22: 작업용장갑 | E22: 9211 | F22: 18274000 | G22: 8454 | H22: 16638000 | I22: 9893 | J22: 19499000 | K22: 9661 | L22: 19024000 | M22: 10434 | N22: 20480000
B23: 공구/전기 | C23: 안전 | D23: 모서리보호 | E23: 536 | F23: 1025000 | G23: 137 | H23: 272000 | I23: 445 | J23: 865000 | K23: 1559 | L23: 3087000 | M23: 3678 | N23: 7295000
B24: 뷰티/퍼스널케어 | C24: 바디용품 | D24: 손소독제
D25: 매장용 소독액
D26: 투명코너매트 | E26: 788 | F26: 7880000 | G26: 635 | H26: 6350000 | I26: 503 | J26: 5030000 | K26: 704 | L26: 7040000 | M26: 141 | N26: 1410000 | O26: 6 | P26: 60000
D27: 고무밴드
F28: =SUM(F22:F27) -> 27179000 | H28: =SUM(H22:H27) -> 23260000 | J28: =SUM(J22:J27) -> 25394000 | L28: =SUM(L22:L27) -> 29151000 | N28: =SUM(N22:N27) -> 29185000 | P28: =SUM(P22:P27) -> 60000

Sheet 5.(매장시설관리팀)
B2: 26년도 현장 안전시설 개선 내역 (1~5월)
B3: 순번 | C3: 매장명 | D3: 유형상세 | E3: 금액 | F3: 일자
B4: 1 | C4: 건대입구점 | D4: 계단핸드레일신규설치 | E4: 1640000 | F4: 2026년 1월
B5: 2 | C5: 죽전본점 | D5: 변압기 보수 | E5: 1300000 | F5: 2026년 1월
B6: 3 | C6: 광주충장로점 | D6: 전동어닝 천 교체 | E6: 865000 | F6: 2026년 1월
B7: 4 | C7: 광주충장로점 | D7: 창고 슬라이딩도어 보수 | E7: 212000 | F7: 2026년 1월
B8: 5 | C8: 신림점 | D8: 타일 보수 | E8: 196000 | F8: 2026년 1월
B9: 6 | C9: 신림점 | D9: 강화도어 보수 | E9: 206000 | F9: 2026년 1월
B10: 7 | C10: 신림점 | D10: 화재감지기 교체보수 | E10: 78000 | F10: 2026년 1월
B11: 8 | C11: 신림점 | D11: 슬로프 논슬립 테이프 시공 | E11: 309000 | F11: 2026년 1월
B12: 9 | C12: 전북대점 | D12: 창고 등기구 교체보수 | E12: 90000 | F12: 2026년 1월
B13: 10 | C13: 전북대점 | D13: 매장 등기구 교체보수 | E13: 193000 | F13: 2026년 1월
B14: 11 | C14: 연신내점 | D14: 사무실 전열 신규 포설 | E14: 55000 | F14: 2026년 1월
B15: 12 | C15: 송내역점 | D15: 매장 등기구 교체보수 | E15: 271000 | F15: 2026년 1월
... B3353: 3350 | C3353: 홈플러스평촌점 | D3353: 등기구 재고정 | E3353: 53000 | F3353: 2026년 5월
